<?xml version="1.0" encoding="UTF-8"?>
<testng-results ignored="0" total="1" passed="0" failed="1" skipped="0">
  <reporter-output>
  </reporter-output>
  <suite started-at="2023-12-09T15:07:32Z" name="Suite" finished-at="2023-12-09T15:07:49Z" duration-ms="17151">
    <groups>
    </groups>
    <test started-at="2023-12-09T15:07:32Z" name="Test" finished-at="2023-12-09T15:07:49Z" duration-ms="17151">
      <class name="tests.ProductTest">
        <test-method is-config="true" signature="openApp()[pri:0, instance:tests.ProductTest@1a942c18]" started-at="2023-12-09T16:07:32Z" name="openApp" finished-at="2023-12-09T16:07:38Z" duration-ms="5584" status="PASS">
          <reporter-output>
          </reporter-output>
        </test-method> <!-- openApp -->
        <test-method signature="productTest(java.lang.String, java.lang.String)[pri:0, instance:tests.ProductTest@1a942c18]" started-at="2023-12-09T16:07:38Z" name="productTest" data-provider="enterLoginData" finished-at="2023-12-09T16:07:47Z" duration-ms="9296" status="FAIL">
          <params>
            <param index="0">
              <value>
                <![CDATA[kjk@gmail.com]]>
              </value>
            </param>
            <param index="1">
              <value>
                <![CDATA[kjk1987]]>
              </value>
            </param>
          </params>
          <exception class="java.lang.AssertionError">
            <message>
              <![CDATA[expected [true] but found [false]]]>
            </message>
            <full-stacktrace>
              <![CDATA[java.lang.AssertionError: expected [true] but found [false]
	at org.testng.Assert.fail(Assert.java:93)
	at org.testng.Assert.failNotEquals(Assert.java:512)
	at org.testng.Assert.assertTrue(Assert.java:41)
	at org.testng.Assert.assertTrue(Assert.java:51)
	at tests.ProductTest.productTest(ProductTest.java:48)
	at java.base/jdk.internal.reflect.DirectMethodHandleAccessor.invoke(DirectMethodHandleAccessor.java:103)
	at java.base/java.lang.reflect.Method.invoke(Method.java:580)
	at org.testng.internal.MethodInvocationHelper.invokeMethod(MethodInvocationHelper.java:108)
	at org.testng.internal.Invoker.invokeMethod(Invoker.java:661)
	at org.testng.internal.Invoker.invokeTestMethod(Invoker.java:869)
	at org.testng.internal.Invoker.invokeTestMethods(Invoker.java:1193)
	at org.testng.internal.TestMethodWorker.invokeTestMethods(TestMethodWorker.java:126)
	at org.testng.internal.TestMethodWorker.run(TestMethodWorker.java:109)
	at org.testng.TestRunner.privateRun(TestRunner.java:744)
	at org.testng.TestRunner.run(TestRunner.java:602)
	at org.testng.SuiteRunner.runTest(SuiteRunner.java:380)
	at org.testng.SuiteRunner.runSequentially(SuiteRunner.java:375)
	at org.testng.SuiteRunner.privateRun(SuiteRunner.java:340)
	at org.testng.SuiteRunner.run(SuiteRunner.java:289)
	at org.testng.SuiteRunnerWorker.runSuite(SuiteRunnerWorker.java:52)
	at org.testng.SuiteRunnerWorker.run(SuiteRunnerWorker.java:86)
	at org.testng.TestNG.runSuitesSequentially(TestNG.java:1301)
	at org.testng.TestNG.runSuitesLocally(TestNG.java:1226)
	at org.testng.TestNG.runSuites(TestNG.java:1144)
	at org.testng.TestNG.run(TestNG.java:1115)
	at org.testng.remote.AbstractRemoteTestNG.run(AbstractRemoteTestNG.java:115)
	at org.testng.remote.RemoteTestNG.initAndRun(RemoteTestNG.java:251)
	at org.testng.remote.RemoteTestNG.main(RemoteTestNG.java:77)
]]>
            </full-stacktrace>
          </exception> <!-- java.lang.AssertionError -->
          <reporter-output>
          </reporter-output>
        </test-method> <!-- productTest -->
        <test-method is-config="true" signature="tearDown()[pri:0, instance:tests.ProductTest@1a942c18]" started-at="2023-12-09T16:07:47Z" name="tearDown" finished-at="2023-12-09T16:07:49Z" duration-ms="2112" status="PASS">
          <reporter-output>
          </reporter-output>
        </test-method> <!-- tearDown -->
      </class> <!-- tests.ProductTest -->
    </test> <!-- Test -->
  </suite> <!-- Suite -->
</testng-results>
